<?xml version="1.0"?>
<robot xmlns:xacro="http://www.ros.org/wiki/xacro">
  <xacro:property name="joint_damping" value="1.0"/>

  <link name="world"/>
  
  <joint name="base_joint" type="fixed">
    <parent link="world"/>
    <child link="base_link"/>
    <origin rpy="0 0 0" xyz="0.0 0.0 0.3"/>
  </joint>
  
  <link
    name="base_link">
    <inertial>
      <origin
        xyz="0 0 2"
        rpy="0 0 0" />
      <mass
        value="0.05" />
      <inertia ixx="0.0001" ixy="0.000"  ixz="0.000"  
         iyy="0.0001" iyz="0.000"
         izz="0.0001"/>
    </inertial>
    <visual>
      <origin
        xyz="0 0 0"
        rpy="0 0 0" />
      <geometry>
        <mesh
          filename="package://nick_bot/meshes/base_link.STL" />
      </geometry>
      <material
        name="">
        <color
          rgba="0.79216 0.81961 0.93333 1" />
      </material>
    </visual>
    <collision>
      <origin
        xyz="0 0 0"
        rpy="0 0 0" />
      <geometry>
        <mesh
          filename="package://nick_bot/meshes/base_link.STL" />
      </geometry>
    </collision>
  </link>
  <link
    name="link_1">
    <inertial>
      <origin
        xyz="0.0061634 0.0010038 0.060589"
        rpy="0 0 0" />
      <mass
        value="0.05" />
      <inertia ixx="0.0001" ixy="0.000"  ixz="0.000"  
         iyy="0.0001" iyz="0.000"
         izz="0.0001"/>
    </inertial>
    <visual>
      <origin
        xyz="0 0 0"
        rpy="0 0 0" />
      <geometry>
        <mesh
          filename="package://nick_bot/meshes/link_1.STL" />
      </geometry>
      <material
        name="">
        <color
          rgba="0.79216 0.81961 0.93333 1" />
      </material>
    </visual>
    <collision>
      <origin
        xyz="0 0 0"
        rpy="0 0 0" />
      <geometry>
        <mesh
          filename="package://nick_bot/meshes/link_1.STL" />
      </geometry>
    </collision>
  </link>
  <joint
    name="joint_1"
    type="revolute">
    <origin
      xyz="0 0 0.064087"
      rpy="0.017453 0 -0.0098054" />
    <parent
      link="base_link" />
    <child
      link="link_1" />
    <axis
      xyz="0 0.017452 0.99985" />
    <limit
      lower="-2.7"
      upper="2.7"
      effort="300.0"
      velocity="4.0" />
  </joint>
  <link
    name="link_2">
    <inertial>
      <origin
        xyz="-0.03205 0.0005952 0.018073"
        rpy="0 0 0" />
      <mass
        value="0.05" />
      <inertia ixx="0.0001" ixy="0.000"  ixz="0.000"  
         iyy="0.0001" iyz="0.000"
         izz="0.0001"/>
    </inertial>
    <visual>
      <origin
        xyz="0 0 0"
        rpy="0 0 0" />
      <geometry>
        <mesh
          filename="package://nick_bot/meshes/link_2.STL" />
      </geometry>
      <material
        name="">
        <color
          rgba="0.79216 0.81961 0.93333 1" />
      </material>
    </visual>
    <collision>
      <origin
        xyz="0 0 0"
        rpy="0 0 0" />
      <geometry>
        <mesh
          filename="package://nick_bot/meshes/link_2.STL" />
      </geometry>
    </collision>
  </link>
  <joint
    name="joint_2"
    type="revolute">
    <origin
      xyz="0 0.0024593 0.14089"
      rpy="1.4125 -0.0087445 -0.0071993" />
    <parent
      link="link_1" />
    <child
      link="link_2" />
    <axis
      xyz="0.99996 -0.0087252 0.0001523" />
    <limit
      lower="-3.5"
      upper="0.6"
      effort="300"
      velocity="4.0" />
  </joint>
  <link
    name="link_3">
    <inertial>
      <origin
        xyz="-0.014774 0.00011596 -0.0036584"
        rpy="0 0 0" />
      <mass
        value="0.05" />
      <inertia ixx="0.0001" ixy="0.000"  ixz="0.000"  
         iyy="0.0001" iyz="0.000"
         izz="0.0001"/>
    </inertial>
    <visual>
      <origin
        xyz="0 0 0"
        rpy="0 0 0" />
      <geometry>
        <mesh
          filename="package://nick_bot/meshes/link_3.STL" />
      </geometry>
      <material
        name="">
        <color
          rgba="0.79216 0.81961 0.93333 1" />
      </material>
    </visual>
    <collision>
      <origin
        xyz="0 0 0"
        rpy="0 0 0" />
      <geometry>
        <mesh
          filename="package://nick_bot/meshes/link_3.STL" />
      </geometry>
    </collision>
  </link>
  <joint
    name="joint_3"
    type="revolute">
    <origin
      xyz="0 0.0019372 0.11098"
      rpy="1.6508 -0.0088619 -0.009271" />
    <parent
      link="link_2" />
    <child
      link="link_3" />
    <axis
      xyz="-0.99996 0.0087252 -0.0001523" />
    <limit
      lower="-0.7"
      upper="4"
      effort="200"
      velocity="4.0" />
  </joint>
  <link
    name="link_4">
    <inertial>
      <origin
        xyz="0.00044646 0.0013719 0.078813"
        rpy="0 0 0" />
      <mass
        value="0.05" />
      <inertia ixx="0.0001" ixy="0.000"  ixz="0.000"  
         iyy="0.0001" iyz="0.000"
         izz="0.0001"/>
    </inertial>
    <visual>
      <origin
        xyz="0 0 0"
        rpy="0 0 0" />
      <geometry>
        <mesh
          filename="package://nick_bot/meshes/link_4.STL" />
      </geometry>
      <material
        name="">
        <color
          rgba="0.79216 0.81961 0.93333 1" />
      </material>
    </visual>
    <collision>
      <origin
        xyz="0 0 0"
        rpy="0 0 0" />
      <geometry>
        <mesh
          filename="package://nick_bot/meshes/link_4.STL" />
      </geometry>
    </collision>
  </link>
  <joint
    name="joint_4"
    type="revolute">
    <origin
      xyz="0 0 0"
      rpy="0.015346 0.017326 1.4497" />
    <parent
      link="link_3" />
    <child
      link="link_4" />
    <axis
      xyz="0 -0.017452 -0.99985" />
    <limit
      lower="-3.1415"
      upper="3.1415"
      effort="300"
      velocity="4.0" />
  </joint>
  <link
    name="link_5">
    <inertial>
      <origin
        xyz="1.3718E-06 -0.011218 0.0025865"
        rpy="0 0 0" />
      <mass
        value="0.05" />
      <inertia ixx="0.0001" ixy="0.000"  ixz="0.000"  
         iyy="0.0001" iyz="0.000"
         izz="0.0001"/>
    </inertial>
    <visual>
      <origin
        xyz="0 0 0"
        rpy="0 0 0" />
      <geometry>
        <mesh
          filename="package://nick_bot/meshes/link_5.STL" />
      </geometry>
      <material name="">
        <color
          rgba="0.79216 0.81961 0.93333 1" />
      </material>
    </visual>
    <collision>
      <origin
        xyz="0 0 0"
        rpy="0 0 0" />
      <geometry>
        <mesh
          filename="package://nick_bot/meshes/link_5.STL" />
      </geometry>
    </collision>
  </link>
  <joint
    name="joint_5"
    type="revolute">
    <origin
      xyz="0 0.0032854 0.18822"
      rpy="-1.909 0.0001523 3.1329" />
    <parent
      link="link_4" />
    <child
      link="link_5" />
    <axis
      xyz="1 0 0" />
    <limit
      lower="0"
      upper="4"
      effort="200"
      velocity="4.0" />
  </joint>
  <link
    name="end_effector">
    <inertial>
      <origin
        xyz="1.2663E-08 0.020431 2.0602E-08"
        rpy="0 0 0" />
      <mass
        value="0.05" />
      <inertia ixx="0.0001" ixy="0.000"  ixz="0.000"  
         iyy="0.0001" iyz="0.000"
         izz="0.0001"/>
    </inertial>
    <visual>
      <origin
        xyz="0 0 0"
        rpy="0 0 0" />
      <geometry>
        <mesh
          filename="package://nick_bot/meshes/end_effector.STL" />
      </geometry>
      <material
        name="">
        <color
          rgba="0.79216 0.81961 0.93333 1" />
      </material>
    </visual>
    <collision>
      <origin
        xyz="0 0 0"
        rpy="0 0 0" />
      <geometry>
        <mesh
          filename="package://nick_bot/meshes/end_effector.STL" />
      </geometry>
    </collision>
  </link>
  <joint
    name="joint_6"
    type="revolute">
    <origin
      xyz="0 0 0"
      rpy="1.5708 0 1.6504" />
    <parent
      link="link_5" />
    <child
      link="end_effector" />
    <axis
      xyz="0 -1 0" />
    <limit
      lower="-3.1415"
      upper="3.1415"
      effort="200"
      velocity="4.0" />
  </joint>
  
  <gazebo reference="link_1">
    <implicitSpringDamper>True</implicitSpringDamper>
   	<selfCollide>false</selfCollide>
    <turnGravityOff>true</turnGravityOff>
	</gazebo>
	<gazebo reference="link_2">
    <implicitSpringDamper>True</implicitSpringDamper>
   	<selfCollide>false</selfCollide>
    <turnGravityOff>true</turnGravityOff>
	</gazebo>

	<gazebo reference="link_3">
    <implicitSpringDamper>True</implicitSpringDamper>
   	<selfCollide>false</selfCollide>
    <turnGravityOff>true</turnGravityOff>
	</gazebo>

	<gazebo reference="link_4">
    <implicitSpringDamper>True</implicitSpringDamper>
   	<selfCollide>false</selfCollide>
    <turnGravityOff>true</turnGravityOff>
	</gazebo>

	<gazebo reference="link_5">
    <implicitSpringDamper>True</implicitSpringDamper>
   	<selfCollide>false</selfCollide>
    <turnGravityOff>true</turnGravityOff>
	</gazebo>
  
	<gazebo reference="end_effector">
    <implicitSpringDamper>True</implicitSpringDamper>
   	<selfCollide>false</selfCollide>
    <turnGravityOff>true</turnGravityOff>
	</gazebo>
  
  
</robot>
