<?xml version="1.0" encoding="utf-8"?>
<!-- GGThis URDF was automatically created by SolidWorks to URDF Exporter! Originally created by Stephen Brawner (brawner@gmail.com) 
     Commit Version: 1.6.0-4-g7f85cfe  Build Version: 1.6.7995.38578
     For more information, please see http://wiki.ros.org/sw_urdf_exporter -->
<robot
  name="nick_bot">
  
  <link name="world"/>
  
  <joint name="base_joint" type="fixed">
    <parent link="world"/>
    <child link="base_link"/>
    <origin rpy="0 0 0" xyz="0.0 0.0 0.0"/>
  </joint>
  
  <link
    name="base_link">
    <inertial>
      <origin
        xyz="-0.0052241 1.0161E-06 0.026639"
        rpy="0 0 0" />
      <mass
        value="0.51245" />
      <inertia
        ixx="0.00046168"
        ixy="-5.6137E-09"
        ixz="-2.8683E-05"
        iyy="0.00064162"
        iyz="-1.7552E-10"
        izz="0.00096413" />
    </inertial>
    <visual>
      <origin
        xyz="0 0 0"
        rpy="0 0 0" />
      <geometry>
        <mesh
          filename="package://nick_bot_1/meshes/base_link.STL" />
      </geometry>
      <material
        name="">
        <color
          rgba="0.79216 0.81961 0.93333 1" />
      </material>
    </visual>
    <collision>
      <origin
        xyz="0 0 0"
        rpy="0 0 0" />
      <geometry>
        <mesh
          filename="package://nick_bot_1/meshes/base_link.STL" />
      </geometry>
    </collision>
  </link>
  <link
    name="link_1">
    <inertial>
      <origin
        xyz="0.0061634 0.0010038 0.060589"
        rpy="0 0 0" />
      <mass
        value="0.28024" />
      <inertia
        ixx="0.00026699"
        ixy="1.8167E-07"
        ixz="2.7958E-05"
        iyy="0.00023186"
        iyz="-1.865E-06"
        izz="0.00013903" />
    </inertial>
    <visual>
      <origin
        xyz="0 0 0"
        rpy="0 0 0" />
      <geometry>
        <mesh
          filename="package://nick_bot_1/meshes/link_1.STL" />
      </geometry>
      <material
        name="">
        <color
          rgba="0.79216 0.81961 0.93333 1" />
      </material>
    </visual>
    <collision>
      <origin
        xyz="0 0 0"
        rpy="0 0 0" />
      <geometry>
        <mesh
          filename="package://nick_bot_1/meshes/link_1.STL" />
      </geometry>
    </collision>
  </link>
  <joint
    name="joint_1"
    type="revolute">
    <origin
      xyz="0 0 0.064087"
      rpy="0.017453 0 -0.0098054" />
    <parent
      link="base_link" />
    <child
      link="link_1" />
    <axis
      xyz="0 0.017452 0.99985" />
    <limit
      lower="-2.7"
      upper="2.7"
      effort="300.0"
      velocity="4.0" />
  </joint>
  <link
    name="link_2">
    <inertial>
      <origin
        xyz="-0.03205 0.0005952 0.018073"
        rpy="0 0 0" />
      <mass
        value="0.29393" />
      <inertia
        ixx="0.00033457"
        ixy="-6.6415E-07"
        ixz="-3.3309E-05"
        iyy="0.00032504"
        iyz="-3.5156E-06"
        izz="0.00010703" />
    </inertial>
    <visual>
      <origin
        xyz="0 0 0"
        rpy="0 0 0" />
      <geometry>
        <mesh
          filename="package://nick_bot_1/meshes/link_2.STL" />
      </geometry>
      <material
        name="">
        <color
          rgba="0.79216 0.81961 0.93333 1" />
      </material>
    </visual>
    <collision>
      <origin
        xyz="0 0 0"
        rpy="0 0 0" />
      <geometry>
        <mesh
          filename="package://nick_bot_1/meshes/link_2.STL" />
      </geometry>
    </collision>
  </link>
  <joint
    name="joint_2"
    type="revolute">
    <origin
      xyz="0 0.0024593 0.14089"
      rpy="1.4125 -0.0087445 -0.0071993" />
    <parent
      link="link_1" />
    <child
      link="link_2" />
    <axis
      xyz="0.99996 -0.0087252 0.0001523" />
    <limit
      lower="-3.5"
      upper="0.6"
      effort="300"
      velocity="4.0" />
  </joint>
  <link
    name="link_3">
    <inertial>
      <origin
        xyz="-0.014774 0.00011596 -0.0036584"
        rpy="0 0 0" />
      <mass
        value="0.085607" />
      <inertia
        ixx="5.4273E-05"
        ixy="-3.1645E-08"
        ixz="7.4467E-07"
        iyy="4.5008E-05"
        iyz="-2.8453E-07"
        izz="3.1724E-05" />
    </inertial>
    <visual>
      <origin
        xyz="0 0 0"
        rpy="0 0 0" />
      <geometry>
        <mesh
          filename="package://nick_bot_1/meshes/link_3.STL" />
      </geometry>
      <material
        name="">
        <color
          rgba="0.79216 0.81961 0.93333 1" />
      </material>
    </visual>
    <collision>
      <origin
        xyz="0 0 0"
        rpy="0 0 0" />
      <geometry>
        <mesh
          filename="package://nick_bot_1/meshes/link_3.STL" />
      </geometry>
    </collision>
  </link>
  <joint
    name="joint_3"
    type="revolute">
    <origin
      xyz="0 0.0019372 0.11098"
      rpy="1.6508 -0.0088619 -0.009271" />
    <parent
      link="link_2" />
    <child
      link="link_3" />
    <axis
      xyz="-0.99996 0.0087252 -0.0001523" />
    <limit
      lower="-0.7"
      upper="4"
      effort="200"
      velocity="4.0" />
  </joint>
  <link
    name="link_4">
    <inertial>
      <origin
        xyz="0.00044646 0.0013719 0.078813"
        rpy="0 0 0" />
      <mass
        value="0.15698" />
      <inertia
        ixx="0.0003485"
        ixy="3.586E-08"
        ixz="-7.8887E-07"
        iyy="0.00035409"
        iyz="-5.1436E-06"
        izz="5.9114E-05" />
    </inertial>
    <visual>
      <origin
        xyz="0 0 0"
        rpy="0 0 0" />
      <geometry>
        <mesh
          filename="package://nick_bot_1/meshes/link_4.STL" />
      </geometry>
      <material
        name="">
        <color
          rgba="0.79216 0.81961 0.93333 1" />
      </material>
    </visual>
    <collision>
      <origin
        xyz="0 0 0"
        rpy="0 0 0" />
      <geometry>
        <mesh
          filename="package://nick_bot_1/meshes/link_4.STL" />
      </geometry>
    </collision>
  </link>
  <joint
    name="joint_4"
    type="revolute">
    <origin
      xyz="0 0 0"
      rpy="0.015346 0.017326 1.4497" />
    <parent
      link="link_3" />
    <child
      link="link_4" />
    <axis
      xyz="0 -0.017452 -0.99985" />
    <limit
      lower="-3.1415"
      upper="3.1415"
      effort="300"
      velocity="4.0" />
  </joint>
  <link
    name="link_5">
    <inertial>
      <origin
        xyz="1.3718E-06 -0.011218 0.0025865"
        rpy="0 0 0" />
      <mass
        value="0.049088" />
      <inertia
        ixx="1.0527E-05"
        ixy="1.4724E-09"
        ixz="-5.9687E-11"
        iyy="1.3447E-05"
        iyz="-1.1209E-06"
        izz="1.7793E-05" />
    </inertial>
    <visual>
      <origin
        xyz="0 0 0"
        rpy="0 0 0" />
      <geometry>
        <mesh
          filename="package://nick_bot_1/meshes/link_5.STL" />
      </geometry>
      <material
        name="">
        <color
          rgba="0.79216 0.81961 0.93333 1" />
      </material>
    </visual>
    <collision>
      <origin
        xyz="0 0 0"
        rpy="0 0 0" />
      <geometry>
        <mesh
          filename="package://nick_bot_1/meshes/link_5.STL" />
      </geometry>
    </collision>
  </link>
  <joint
    name="joint_5"
    type="revolute">
    <origin
      xyz="0 0.0032854 0.18822"
      rpy="-1.909 0.0001523 3.1329" />
    <parent
      link="link_4" />
    <child
      link="link_5" />
    <axis
      xyz="1 0 0" />
    <limit
      lower="0"
      upper="4"
      effort="200"
      velocity="4.0" />
  </joint>
  <link
    name="end_effector">
    <inertial>
      <origin
        xyz="1.2663E-08 0.020431 2.0602E-08"
        rpy="0 0 0" />
      <mass
        value="0.01147" />
      <inertia
        ixx="9.3427E-07"
        ixy="-3.723E-12"
        ixz="2.2266E-12"
        iyy="1.2077E-06"
        iyz="-1.4872E-12"
        izz="9.3426E-07" />
    </inertial>
    <visual>
      <origin
        xyz="0 0 0"
        rpy="0 0 0" />
      <geometry>
        <mesh
          filename="package://nick_bot_1/meshes/end_effector.STL" />
      </geometry>
      <material
        name="">
        <color
          rgba="0.79216 0.81961 0.93333 1" />
      </material>
    </visual>
    <collision>
      <origin
        xyz="0 0 0"
        rpy="0 0 0" />
      <geometry>
        <mesh
          filename="package://nick_bot_1/meshes/end_effector.STL" />
      </geometry>
    </collision>
  </link>
  <joint
    name="joint_6"
    type="revolute">
    <origin
      xyz="0 0 0"
      rpy="1.5708 0 1.6504" />
    <parent
      link="link_5" />
    <child
      link="end_effector" />
    <axis
      xyz="0 -1 0" />
    <limit
      lower="-3.1415"
      upper="3.1415"
      effort="200"
      velocity="4.0" />
  </joint>
  <gazebo>
	<plugin name="gazebo_ros2_control"
	filename="libgazebo_ros2_control.so">
	<parameters>$(find nick_bot)/config/nickbot_controllers.yaml</parameters>
	</plugin>
  </gazebo>
  	
  <ros2_control name="GazeboSystem" type="system">
  	<hardware>
  	  <plugin>gazebo_ros2_control/GazeboSystem</plugin>
  	</hardware>
  	<joint name="joint_1">
  	  <command_interface name="position"/>
  	  <state_interface name="position">
  	    <param name="initial_value">0.0</param>
  	   </state_interface>
  	   <state_interface name="velocity"/>
  	</joint>   
  </ros2_control>
	<ros2_control name="GazeboSystem" type="system">
	  	<joint name="joint_2">
	  	  <command_interface name="position"/>
	  	  <state_interface name="position">
	  	    <param name="initial_value">0.0</param>
	  	   </state_interface>
	  	   <state_interface name="velocity"/>
	  	</joint>   
	  </ros2_control>		
  <ros2_control name="GazeboSystem" type="system">
  	<joint name="joint_3">
  	  <command_interface name="position"/>
  	  <state_interface name="position">
  	    <param name="initial_value">0.0</param>
  	   </state_interface>
  	   <state_interface name="velocity"/>
  	</joint>   
  </ros2_control>
  <ros2_control name="GazeboSystem" type="system">
  	<joint name="joint_4">
  	  <command_interface name="position"/>
  	  <state_interface name="position">
  	    <param name="initial_value">0.0</param>
  	   </state_interface>
  	   <state_interface name="velocity"/>
  	</joint>   
  </ros2_control>
  <ros2_control name="GazeboSystem" type="system">
  	<joint name="joint_5">
  	  <command_interface name="position"/>
  	  <state_interface name="position">
  	    <param name="initial_value">0.0</param>
  	   </state_interface>
  	   <state_interface name="velocity"/>
  	</joint>   
  </ros2_control>
  <ros2_control name="GazeboSystem" type="system">
  	<joint name="joint_6">
  	  <command_interface name="position"/>
  	  <state_interface name="position">
  	    <param name="initial_value">0.0</param>
  	   </state_interface>
  	   <state_interface name="velocity"/>
  	</joint>   
  </ros2_control>	
</robot>
