<?xml version="1.0" encoding="utf-8"?>
<!-- ohnThis URDF was automatically created by SolidWorks to URDF Exporter! Originally created by Stephen Brawner (brawner@gmail.com) 
     Commit Version: 1.6.0-4-g7f85cfe  Build Version: 1.6.7995.38578
     For more information, please see http://wiki.ros.org/sw_urdf_exporter -->
<robot
  name="nick_bot">
  
  
  
  <link name="world"/>
  
  <joint name="base_joint" type="fixed">
    <parent link="world"/>
    <child link="base_link"/>
    <origin rpy="0 0 0" xyz="0.0 0.0 0.3"/>
  </joint>
  
  <link
    name="base_link">
    <inertial>
      <origin
        xyz="-0.00522413960660934 1.01612793732535E-06 0.0266388152879452"
        rpy="0 0 0" />
      <mass
        value="0.05" />
      <inertia ixx="0.0001" ixy="0.000"  ixz="0.000"  
         iyy="0.0001" iyz="0.000"
         izz="0.0001"/>
    </inertial>
    <visual>
      <origin
        xyz="0 0 0"
        rpy="0 0 0" />
      <geometry>
        <mesh
          filename="package://nick_bot/meshes/base_link.STL" />
      </geometry>
      <material
        name="">
        <color
          rgba="0.792156862745098 0.819607843137255 0.933333333333333 1" />
      </material>
    </visual>
    <collision>
      <origin
        xyz="0 0 0"
        rpy="0 0 0" />
      <geometry>
        <mesh
          filename="package://nick_bot/meshes/base_link.STL" />
      </geometry>
    </collision>
  </link>
  <link
    name="link_1">
    <inertial>
      <origin
        xyz="0.00616337962890819 0.00100379018116143 0.0605890124959618"
        rpy="0 0 0" />
      <mass
        value="0.05" />
      <inertia ixx="0.0001" ixy="0.000"  ixz="0.000"  
         iyy="0.0001" iyz="0.000"
         izz="0.0001"/>
    </inertial>
    <visual>
      <origin
        xyz="0 0 0"
        rpy="0 0 0" />
      <geometry>
        <mesh
          filename="package://nick_bot/meshes/link_1.STL" />
      </geometry>
      <material
        name="">
        <color
          rgba="0.792156862745098 0.819607843137255 0.933333333333333 1" />
      </material>
    </visual>
    <collision>
      <origin
        xyz="0 0 0"
        rpy="0 0 0" />
      <geometry>
        <mesh
          filename="package://nick_bot/meshes/link_1.STL" />
      </geometry>
    </collision>
  </link>
  <joint
    name="joint_1"
    type="revolute">
    <origin
      xyz="0 0 0.064087"
      rpy="0.017453 0 -1.5621" />
    <parent
      link="base_link" />
    <child
      link="link_1" />
    <axis
      xyz="0 -0.017452 -0.99985" />
    <limit
      lower="-1.75"
      upper="1.75"
      effort="0"
      velocity="0" />
  </joint>
  <link
    name="link_2">
    <inertial>
      <origin
        xyz="-0.0320499775068787 0.000595202453078758 0.018073123575994"
        rpy="0 0 0" />
      <mass
        value="0.05" />
      <inertia ixx="0.0001" ixy="0.000"  ixz="0.000"  
         iyy="0.0001" iyz="0.000"
         izz="0.0001"/>
    </inertial>
    <visual>
      <origin
        xyz="0 0 0"
        rpy="0 0 0" />
      <geometry>
        <mesh
          filename="package://nick_bot/meshes/link_2.STL" />
      </geometry>
      <material
        name="">
        <color
          rgba="0.792156862745098 0.819607843137255 0.933333333333333 1" />
      </material>
    </visual>
    <collision>
      <origin
        xyz="0 0 0"
        rpy="0 0 0" />
      <geometry>
        <mesh
          filename="package://nick_bot/meshes/link_2.STL" />
      </geometry>
    </collision>
  </link>
  <joint
    name="joint_2"
    type="revolute">
    <origin
      xyz="0 0.0024593 0.14089"
      rpy="1.4835 -0.0088311 -0.0078131" />
    <parent
      link="link_1" />
    <child
      link="link_2" />
    <axis
      xyz="-0.99996 0.0087252 -0.0001523" />
    <limit
      lower="-0.6"
      upper="3.6"
      effort="0"
      velocity="0" />
  </joint>
  <link
    name="link_3">
    <inertial>
      <origin
        xyz="-0.0147738927835156 0.000115773286870235 -0.00365845437443535"
        rpy="0 0 0" />
      <mass
        value="0.05" />
      <inertia ixx="0.0001" ixy="0.000"  ixz="0.000"  
         iyy="0.0001" iyz="0.000"
         izz="0.0001"/>
    </inertial>
    <visual>
      <origin
        xyz="0 0 0"
        rpy="0 0 0" />
      <geometry>
        <mesh
          filename="package://nick_bot/meshes/link_3.STL" />
      </geometry>
      <material
        name="">
        <color
          rgba="0.792156862745098 0.819607843137255 0.933333333333333 1" />
      </material>
    </visual>
    <collision>
      <origin
        xyz="0 0 0"
        rpy="0 0 0" />
      <geometry>
        <mesh
          filename="package://nick_bot/meshes/link_3.STL" />
      </geometry>
    </collision>
  </link>
  <joint
    name="joint_3"
    type="revolute">
    <origin
      xyz="0 0.0019372 0.11098"
      rpy="-1.9199 0.0079947 -0.011853" />
    <parent
      link="link_2" />
    <child
      link="link_3" />
    <axis
      xyz="-0.99996 0.0087252 -0.0001523" />
    <limit
      lower="-4.2"
      upper="0"
      effort="0"
      velocity="0" />
  </joint>
  <link
    name="link_4">
    <inertial>
      <origin
        xyz="0.000446439621704181 0.00137190367562623 0.0788129649196884"
        rpy="0 0 0" />
      <mass
        value="0.05" />
      <inertia ixx="0.0001" ixy="0.000"  ixz="0.000"  
         iyy="0.0001" iyz="0.000"
         izz="0.0001"/>
    </inertial>
    <visual>
      <origin
        xyz="0 0 0"
        rpy="0 0 0" />
      <geometry>
        <mesh
          filename="package://nick_bot/meshes/link_4.STL" />
      </geometry>
      <material
        name="">
        <color
          rgba="0.792156862745098 0.819607843137255 0.933333333333333 1" />
      </material>
    </visual>
    <collision>
      <origin
        xyz="0 0 0"
        rpy="0 0 0" />
      <geometry>
        <mesh
          filename="package://nick_bot/meshes/link_4.STL" />
      </geometry>
    </collision>
  </link>
  <joint
    name="joint_4"
    type="revolute">
    <origin
      xyz="0 0 0"
      rpy="0.017453 -0.017453 -1.5708" />
    <parent
      link="link_3" />
    <child
      link="link_4" />
    <axis
      xyz="0 -0.017452 -0.99985" />
    <limit
      lower="-1.5"
      upper="2"
      effort="0"
      velocity="0" />
  </joint>
  <link
    name="link_5">
    <inertial>
      <origin
        xyz="1.37814036968442E-06 -0.0112175744982041 0.00258648216033591"
        rpy="0 0 0" />
      <mass
        value="0.05" />
      <inertia ixx="0.0001" ixy="0.000"  ixz="0.000"  
         iyy="0.0001" iyz="0.000"
         izz="0.0001"/>
    </inertial>
    <visual>
      <origin
        xyz="0 0 0"
        rpy="0 0 0" />
      <geometry>
        <mesh
          filename="package://nick_bot/meshes/link_5.STL" />
      </geometry>
      <material
        name="">
        <color
          rgba="0.792156862745098 0.819607843137255 0.933333333333333 1" />
      </material>
    </visual>
    <collision>
      <origin
        xyz="0 0 0"
        rpy="0 0 0" />
      <geometry>
        <mesh
          filename="package://nick_bot/meshes/link_5.STL" />
      </geometry>
    </collision>
  </link>
  <joint
    name="joint_5"
    type="revolute">
    <origin
      xyz="0 0.0032854 0.18822"
      rpy="-0.017453 -0.0001523 -0.0087253" />
    <parent
      link="link_4" />
    <child
      link="link_5" />
    <axis
      xyz="-1 0 0" />
    <limit
      lower="-2.35"
      upper="2.35"
      effort="0"
      velocity="0" />
  </joint>
  <link
    name="end_effector">
    <inertial>
      <origin
        xyz="-1.66377830262965E-08 0.0204269190545232 3.44363878523879E-08"
        rpy="0 0 0" />
      <mass
        value="0.05" />
      <inertia ixx="0.0001" ixy="0.000"  ixz="0.000"  
         iyy="0.0001" iyz="0.000"
         izz="0.0001"/>
    </inertial>
    <visual>
      <origin
        xyz="0 0 0"
        rpy="0 0 0" />
      <geometry>
        <mesh
          filename="package://nick_bot/meshes/end_effector.STL" />
      </geometry>
      <material
        name="">
        <color
          rgba="0.792156862745098 0.819607843137255 0.933333333333333 1" />
      </material>
    </visual>
    <collision>
      <origin
        xyz="0 0 0"
        rpy="0 0 0" />
      <geometry>
        <mesh
          filename="package://nick_bot/meshes/end_effector.STL" />
      </geometry>
    </collision>
  </link>
  <joint
    name="joint_6"
    type="continuous">
    <origin
      xyz="0 0 0"
      rpy="1.5708 0 2.2137" />
    <parent
      link="link_5" />
    <child
      link="end_effector" />
    <axis
      xyz="0 -1 0" />
  </joint>
  
  <transmission name="link_1_trans">
    <type>transmission_interface/SimpleTransmission</type>
   <joint name="joint_1">
     <hardwareInterface>hardware_interface/PositionJointInterface</hardwareInterface>
   </joint>
   <actuator name="link_1_motor">
   
   <hardwareInterface>hardware_interface/PositionJointInterface</hardwareInterface>
       <mechanicalReduction>1</mechanicalReduction>
   </actuator>
   	</transmission>
   
     <transmission name="link_2_trans">
    <type>transmission_interface/SimpleTransmission</type>
   <joint name="joint_2">
     <hardwareInterface>hardware_interface/PositionJointInterface</hardwareInterface>
   </joint>
   <actuator name="link_2_motor">
   
   <hardwareInterface>hardware_interface/PositionJointInterface</hardwareInterface>
       <mechanicalReduction>1</mechanicalReduction>
   </actuator>
   	</transmission>
   
     <transmission name="link_3_trans">
    <type>transmission_interface/SimpleTransmission</type>
   <joint name="joint_3">
     <hardwareInterface>hardware_interface/PositionJointInterface</hardwareInterface>
   </joint>
   <actuator name="link_3_motor">
   
   <hardwareInterface>hardware_interface/PositionJointInterface</hardwareInterface>
       <mechanicalReduction>1</mechanicalReduction>
   </actuator>
	</transmission>
	
	<transmission name="link_4_trans">
    <type>transmission_interface/SimpleTransmission</type>
   <joint name="joint_4">
     <hardwareInterface>hardware_interface/PositionJointInterface</hardwareInterface>
   </joint>
   <actuator name="link_4_motor">
   
   <hardwareInterface>hardware_interface/PositionJointInterface</hardwareInterface>
       <mechanicalReduction>1</mechanicalReduction>
   </actuator>
	</transmission>
	
	<transmission name="link_5_trans">
    <type>transmission_interface/SimpleTransmission</type>
   <joint name="joint_5">
     <hardwareInterface>hardware_interface/PositionJointInterface</hardwareInterface>
   </joint>
   <actuator name="link_5_motor">
   
   <hardwareInterface>hardware_interface/PositionJointInterface</hardwareInterface>
       <mechanicalReduction>1</mechanicalReduction>
   </actuator>
	</transmission>
	
	<transmission name="end_effector_trans">
    <type>transmission_interface/SimpleTransmission</type>
   <joint name="joint_6">
     <hardwareInterface>hardware_interface/PositionJointInterface</hardwareInterface>
   </joint>
   <actuator name="end_effector_motor">
   
   <hardwareInterface>hardware_interface/PositionJointInterface</hardwareInterface>
       <mechanicalReduction>1</mechanicalReduction>
   </actuator>
	</transmission>
	
  <gazebo>
	<plugin name="gazebo_ros2_control"
	filename="libgazebo_ros2_control.so">
	<parameters>$(find nick_bot)/config/nickbot_controllers.yaml</parameters>
	</plugin>
  </gazebo>
  
  
  <gazebo reference="link_1">
	<selfCollide>true</selfCollide>
  </gazebo>

	<gazebo reference="link_2">
		<selfCollide>true</selfCollide>
	</gazebo>

	<gazebo reference="link_3">
		<selfCollide>true</selfCollide>
	</gazebo>

	<gazebo reference="link_4">
		<selfCollide>true</selfCollide>
	</gazebo>

	<gazebo reference="link_5">
		<selfCollide>true</selfCollide>
	</gazebo>

	<gazebo reference="end_effector">
		<selfCollide>true</selfCollide>
	</gazebo>
	
  <ros2_control name="GazeboSystem" type="system">
  	<hardware>
  	  <plugin>gazebo_ros2_control/GazeboSystem</plugin>
  	</hardware>
  	<joint name="joint_1">
  	  <command_interface name="position"/>
  	  <state_interface name="position">
  	    <param name="initial_value">0.0</param>
  	   </state_interface>
  	   <state_interface name="velocity"/>
  	</joint>   
  </ros2_control>
  <ros2_control name="GazeboSystem" type="system">
  	<joint name="joint_2">
  	  <command_interface name="position"/>
  	  <state_interface name="position">
  	    <param name="initial_value">0.0</param>
  	   </state_interface>
  	   <state_interface name="velocity"/>
  	</joint>   
  </ros2_control>		
  <ros2_control name="GazeboSystem" type="system">
  	<joint name="joint_3">
  	  <command_interface name="position"/>
  	  <state_interface name="position">
  	    <param name="initial_value">0.0</param>
  	   </state_interface>
  	   <state_interface name="velocity"/>
  	</joint>   
  </ros2_control>
<ros2_control name="GazeboSystem" type="system">
  	<joint name="joint_4">
  	  <command_interface name="position"/>
  	  <state_interface name="position">
  	    <param name="initial_value">0.0</param>
  	   </state_interface>
  	   <state_interface name="velocity"/>
  	</joint>   
  </ros2_control>
  <ros2_control name="GazeboSystem" type="system">
  	<joint name="joint_5">
  	  <command_interface name="position"/>
  	  <state_interface name="position">
  	    <param name="initial_value">0.0</param>
  	   </state_interface>
  	   <state_interface name="velocity"/>
  	</joint>   
  </ros2_control>
  <ros2_control name="GazeboSystem" type="system">
  	<joint name="joint_6">
  	  <command_interface name="position"/>
  	  <state_interface name="position">
  	    <param name="initial_value">0.0</param>
  	   </state_interface>
  	   <state_interface name="velocity"/>
  	</joint>   
  </ros2_control>
  <gazebo>
	  <plugin name="gazebo_ros2_control"
	    filename="libgazebo_ros2_control.so">
	    <parameters>$(find nick_bot)/config/nickbot_controllers.yaml</parameters>
	  </plugin>
  </gazebo>
  	
</robot>
